Workbook

Sheet Sheet
A1: Пожалуйста, введите свой ID, который вы получили после подписания соглашения на участие. | B1: Вы уехали из России после 24-го февраля 2022 года? / Did you leave Russia after February 24th 2022? | D1: В данный момент вы проживаете в Грузии или Армении?/ Are you currently residing in Georgia or Armenia? | F1: Вы свободно говорите по-русски? / Are you fluent in Russian? | H1: Ваш пол / Gender | K1: Возраста / Age | R1: Укажите вашу этническую принадлежнось / Which ethnicity best describes you? | T1: На каких языках вы разговариваете? / What languages do you speak? | U1: Из какого города/села вы эмигрировали (название, область)? / What place did you emigrate from? | V1: В каком городе/селе вы сейчас находитесь (название, страна)? Where are you residing now? | W1: Семейное положение / Which of the following best describes your current relationship status? | AD1: У вас есть дети моложе 18 лет? / Do you have any children under 18? | AF1: Если да, то сколько? / If yes, how many? | AG1: Есть ли у вас другие члены семьи на иждивении? / Do you have any other dependents who are currently living with you | AI1: Если да, то сколько? / If yes, how many? | AJ1: Уровень образования / Highest level of education: | AR1: Какой у вас уровень доходов? / What is your current income? | AU1: Почему вы решили уехать из России? / What were your reasons for leaving Russia? | AV1: Я не доверяю людям в этой стране. / I do not trust the people of this country. | AZ1: Я скучаю по атмосфере моего родного города (села). / I miss the atmosphere of my hometown. | BD1: Социум постоянно напоминает мне, что я иммигрант. / Society constantly reminds you that you are an immigrant. | BH1: Я чувствую себя одиноким. / I feel alone. | BL1: У меня слишком много обязанностей. / I have too many responsibilities. | BP1: Меня беспокоит, что я не смогу дать моим детям образование, которое будет соответствовать моей культуре. / It worries me that I cannot educate my children according to my culture. | BT1: Я чувствую, что я потерпел неудачу. / I feel that I have failed. | BX1: Я чувствую, что я не принадлежу к этому обществу. / I feel that I do not belong to this society. | CB1: Я боюсь, что я потерплю неудачу в этой стране. / I fear that I will fail in this country. | CF1: Я не чувствую себя здесь принятым. / I do not feel accepted here. | CJ1: Я чувствую себя очень плохо, когда я думаю о том, что я оставил в своей стране. / I feel very bad when I think about everything I left behind in my country. | CN1: Я переживаю за свое здоровье. / I am worried about my health. | CR1: У меня нет адекватного жилья. / I do not have adequate housing. | CV1: Я чувствую вину за то, что я оставил свою семью. / I feel guilty for having left my family. | CZ1: Я чувствую как будто я бросил свою семью. / I feel like I have abandoned my family. | DD1: Я скучаю по своей семье. / I miss my family. | DH1: Я часто чувствую себя напряженным. / I frequently feel tense. | DL1: Я не уверен, что я хочу здесь остаться. / I am not sure if I want to stay here. | DP1: У меня есть финансовые проблемы. / I have financial problems. | DT1: Мне очень сложно решить свои проблемы. / It is very difficult for me to solve my problems. | DX1: Я жалею, что я покинул свою страну. / I regret having left my country. | EB1: С тех пор как я сюда переехал, моя жизнь стала хуже. / Since I moved here my life has gotten worse. | EF1: Я переживаю, что я вовлек других людей в свое желание эмигрировать. / It worries me that I have involved other people in my decision to immigrate. | EJ1: Я чувствую, что моя культура недооценена. / I have felt that my culture is undervalued. | EN1: Я чувствую давление от жителей этой страны принять их стиль жизни. / I feel pressured by the people of this country to adopt their lifestyle. | ER1: В этой стране иммигранты не имеют возможности получить высокие должности. / In this country, immigrants do not have the opportunity to obtain higher ranking jobs. | EV1: Я переживаю, что я не смогу содержать свою семью. / I am worried that I cannot support my family. | EZ1: Я не чувствую себя хорошо в этой стране. / I don't feel good in this country. | FD1: Я чувствую дискриминацию, когда я пытаюсь найти жилье. / I feel discriminated against when it comes to finding housing. | FH1: Я очень волнуюсь за свою страну происхождения. / I worry a lot about my country of origin. | FL1: Я чувствую, что я никогда не смогу вернуться на родину. / I feel like I will never be able to come back to my homeland. | FP1: Отсутствие жилья / Lack of shelter | FR1: Отсутствие еды или воды / Lack of food or water | FT1: Плохое здоровье без доступа к медицинской помощи / Ill health without access to medical care | FV1: Конфискация имущества / Confiscation of personal property | FX1: Избиение / Beating to the body | FZ1: Изнасилование / Rape | GB1: Другие виды сексуального домогательства или унижения / Other types of sexual abuse or sexual humiliation | GD1: Арест / Imprisonment | GF1: Рэкет или ограбление / Extortion or robbery | GH1: Промывка мозгов / Brainwashing | GJ1: Разделение с членами семьи / Separation from family members | GL1: Предательство члена семьи или друга / Betrayal of family member, or friend | GN1: Присутствие при избиении другого человека / Witness beating to head or body | GP1: Присутствие при пытках / Witness torture | GR1: Присутствие при изнасиловании или сексуальных домогательствах / Witness rape or sexual abuse | GT1: Утопление / Near drowning | GV1: Голод / Starvation | GX1: Пожалуйста, перечислите другие ситуации, в которых вы сильно испугались или почувствовали, что вашей жизни угрожает опасность. / Please list any other situations not included above that were very frightening or in which you felt your life was in danger. | GY1: Насколько нижеприведенные симптомы вас беспокоили в течение последней недели? | IQ1: Насколько нижеприведенные симптомы беспокоили вас в течение последней недели? / How much have the following symptoms bothered you in the past week? | JS1: Насколько нижеприведенные симптомы беспокоили вас в течение последней недели? / How much have the following symptoms bothered you in the past week? | KU1: Внезапный страх без видимой причины / Suddenly scared for no reason | KY1: Чувство пугливости / Feeling fearful | LC1: Обморочность, головокуржение, слабость / Faintness, dizziness or weakness | LG1: Нервозность или внутренняя дрожь / Nervousness or shakiness inside | LK1: Сердебиение или учащение пульса / Heart pounding or racing | LO1: Тремор / Trembling | LS1: Напряжение, взвинченность / Feeling tense or keyed up | LW1: Головная боль / Headaches | MA1: Присуп ужаса, паники / Spell of terror or panic | ME1: Ощущение тревожности, не можете найти себе место / Feeling restless or can’t sit still | MI1: Ощущение вялости, заторможенности / Feeling low in energy, slowed down | MM1: Обвиняете себя за что-либо / Blaming yourself for things | MQ1: Легко начинаете плакать / Crying easily | MU1: Утрата сексуального влечения или удовольствия / Loss of sexual interest or pleasure | MY1: Плохой аппетит / Poor appetite | NC1: Сложности с засыпанием или со сном / Difficulty falling asleep, staying asleep | NG1: Чувство безнадежности в отношении будущего / Feeling hopeless about future | NK1: Подавленное настроение / Feeling blue | NO1: Чувство одиночества / Feeling lonely | NS1: Чувство, что вы в ловушке или пойманы / Feeling of being trapped or caught | NW1: Чрезмерное беспокойство по незначительным поводам / Worry too much about things | OA1: Отсутствие интереса к чему-либо / Feeling no interest in things | OE1: Ощущение, что все дается с трудом / Feeling everything is an effort | OI1: Ощущение своей никчемности / Feeling of worthlessness
A2: Open-Ended Response | B2: Да / Yes | C2: Нет / No | D2: Да / Yes | E2: Нет / No | F2: Да / Yes | G2: Нет / No | H2: Женский / Female | I2: Мужской / Male | J2: Небинарный / Non-binary | K2: Моложе 18 | L2: 18-24 | M2: 25-34 | N2: 35-44 | O2: 45-54 | P2: 55-64 | Q2: 65+ | R2: Русский(ая) / Russian | S2: Другая этническая принадлежность (уточните) / Other (please specify) | T2: Open-Ended Response | U2: Open-Ended Response | V2: Open-Ended Response | W2: Женат (замужем) / Married | X2: Вдовец (вдова) / Widowed | Y2: В разводе / Divorced | Z2: Раздельное проживание / Separated | AA2: Гражданский брак / Cohabiting with a significant other or in a domestic partnership | AB2: Никогда не был женат (замужем) / Single, never married | AC2: Предпочитаю не отвечать / Prefer not to answer | AD2: Да / Yes | AE2: Нет / No | AF2: Open-Ended Response | AG2: Да / Yes | AH2: Нет / No | AI2: Open-Ended Response | AJ2: Незаконченное среднее образование / Less than high school graduate | AK2: Среднее образование / High school graduate | AL2: Незаконченное высшее / Some college | AM2: Высшее образование (бакалавриат) / Bachelor’s Degree | AN2: Высшее образование (специалист) / 5 years of college | AO2: Магистратура / Master’s Degree | AP2: Кандидат наук / Doctoral Degree | AQ2: Профессиональное образование / Professional Degree | AR2: Ниже среднего / Below average | AS2: Средний / Average | AT2: Выше среднего / Above average | AU2: Open-Ended Response | AV2: Полностью согласен / Strongly agree | AW2: Скорее согласен / Moderately agree | AX2: Скорее не согласен / Moderately disagree | AY2: Полностью не согласен / Strongly disagree | AZ2: Полностью согласен / Strongly agree | BA2: Скорее согласен / Moderately agree | BB2: Скорее не согласен / Moderately disagree | BC2: Полностью не согласен / Strongly disagree | BD2: Полностью согласен / Strongly agree | BE2: Скорее согласен / Moderately agree | BF2: Скорее не согласен / Moderately disagree | BG2: Полностью не согласен / Strongly disagree | BH2: Полностью согласен / Strongly agree | BI2: Скорее согласен / Moderately agree | BJ2: Скорее не согласен / Moderately disagree | BK2: Полностью не согласен / Strongly disagree | BL2: Полностью согласен / Strongly agree | BM2: Скорее согласен / Moderately agree | BN2: Скорее не согласен / Moderately disagree | BO2: Полностью не согласен / Strongly disagree | BP2: Полностью согласен / Strongly agree | BQ2: Скорее согласен / Moderately agree | BR2: Скорее не согласен / Moderately disagree | BS2: Полностью не согласен / Strongly disagree | BT2: Полностью согласен / Strongly agree | BU2: Скорее согласен / Moderately agree | BV2: Скорее не согласен / Moderately disagree | BW2: Полностью не согласен / Strongly disagree | BX2: Полностью согласен / Strongly agree | BY2: Скорее согласен / Moderately agree | BZ2: Скорее не согласен / Moderately disagree | CA2: Полностью не согласен / Strongly disagree | CB2: Полностью согласен / Strongly agree | CC2: Скорее согласен / Moderately agree | CD2: Скорее не согласен / Moderately disagree | CE2: Полностью не согласен / Strongly disagree | CF2: Полностью согласен / Strongly agree | CG2: Скорее согласен / Moderately agree | CH2: Скорее не согласен / Moderately disagree | CI2: Полностью не согласен / Strongly disagree | CJ2: Полностью согласен / Strongly agree | CK2: Скорее согласен / Moderately agree | CL2: Скорее не согласен / Moderately disagree | CM2: Полностью не согласен / Strongly disagree | CN2: Полностью согласен / Strongly agree | CO2: Скорее согласен / Moderately agree | CP2: Скорее не согласен / Moderately disagree | CQ2: Полностью не согласен / Strongly disagree | CR2: Полностью согласен / Strongly agree | CS2: Скорее согласен / Moderately agree | CT2: Скорее не согласен / Moderately disagree | CU2: Полностью не согласен / Strongly disagree | CV2: Полностью согласен / Strongly agree | CW2: Скорее согласен / Moderately agree | CX2: Скорее не согласен / Moderately disagree | CY2: Полностью не согласен / Strongly disagree | CZ2: Полностью согласен / Strongly agree | DA2: Скорее согласен / Moderately agree | DB2: Скорее не согласен / Moderately disagree | DC2: Полностью не согласен / Strongly disagree | DD2: Полностью согласен / Strongly agree | DE2: Скорее согласен / Moderately agree | DF2: Скорее не согласен / Moderately disagree | DG2: Полностью не согласен / Strongly disagree | DH2: Полностью согласен / Strongly agree | DI2: Скорее согласен / Moderately agree | DJ2: Скорее не согласен / Moderately disagree | DK2: Полностью не согласен / Strongly disagree | DL2: Полностью согласен / Strongly agree | DM2: Скорее согласен / Moderately agree | DN2: Скорее не согласен / Moderately disagree | DO2: Полностью не согласен / Strongly disagree | DP2: Полностью согласен / Strongly agree | DQ2: Скорее согласен / Moderately agree | DR2: Скорее не согласен / Moderately disagree | DS2: Полностью не согласен / Strongly disagree | DT2: Полностью согласен / Strongly agree | DU2: Скорее согласен / Moderately agree | DV2: Скорее не согласен / Moderately disagree | DW2: Полностью не согласен / Strongly disagree | DX2: Полностью согласен / Strongly agree | DY2: Скорее согласен / Moderately agree | DZ2: Скорее не согласен / Moderately disagree | EA2: Полностью не согласен / Strongly disagree | EB2: Полностью согласен / Strongly agree | EC2: Скорее согласен / Moderately agree | ED2: Скорее не согласен / Moderately disagree | EE2: Полностью не согласен / Strongly disagree | EF2: Полностью согласен / Strongly agree | EG2: Скорее согласен / Moderately agree | EH2: Скорее не согласен / Moderately disagree | EI2: Полностью не согласен / Strongly disagree | EJ2: Полностью согласен / Strongly agree | EK2: Скорее согласен / Moderately agree | EL2: Скорее не согласен / Moderately disagree | EM2: Полностью не согласен / Strongly disagree | EN2: Полностью согласен / Strongly agree | EO2: Скорее согласен / Moderately agree | EP2: Скорее не согласен / Moderately disagree | EQ2: Полностью не согласен / Strongly disagree | ER2: Полностью согласен / Strongly agree | ES2: Скорее согласен / Moderately agree | ET2: Скорее не согласен / Moderately disagree | EU2: Полностью не согласен / Strongly disagree | EV2: Полностью согласен / Strongly agree | EW2: Скорее согласен / Moderately agree | EX2: Скорее не согласен / Moderately disagree | EY2: Полностью не согласен / Strongly disagree | EZ2: Полностью согласен / Strongly agree | FA2: Скорее согласен / Moderately agree | FB2: Скорее не согласен / Moderately disagree | FC2: Полностью не согласен / Strongly disagree | FD2: Полностью согласен / Strongly agree | FE2: Скорее согласен / Moderately agree | FF2: Скорее не согласен / Moderately disagree | FG2: Полностью не согласен / Strongly disagree | FH2: Полностью согласен / Strongly agree | FI2: Скорее согласен / Moderately agree | FJ2: Скорее не согласен / Moderately disagree | FK2: Полностью не согласен / Strongly disagree | FL2: Полностью согласен / Strongly agree | FM2: Скорее согласен / Moderately agree | FN2: Скорее не согласен / Moderately disagree | FO2: Полностью не согласен / Strongly disagree | FP2: Да / Yes | FQ2: Нет / No | FR2: Да / Yes | FS2: Нет / No | FT2: Да / Yes | FU2: Нет / No | FV2: Да / Yes | FW2: Нет / No | FX2: Да / Yes | FY2: Нет / No | FZ2: Да / Yes | GA2: Нет / No | GB2: Да / Yes | GC2: Нет / No | GD2: Да / Yes | GE2: Нет / No | GF2: Да / Yes | GG2: Нет / No | GH2: Да / Yes | GI2: Нет / No | GJ2: Да / Yes | GK2: Нет / No | GL2: Да / Yes | GM2: Нет / No | GN2: Да / Yes | GO2: Нет / No | GP2: Да / Yes | GQ2: Нет / No | GR2: Да / Yes | GS2: Нет / No | GT2: Да / Yes | GU2: Нет / No | GV2: Да / Yes | GW2: Нет / No | GX2: Open-Ended Response | GY2: Навязчивые мысли и воспоминания о наиболее болезненных или пугающих событиях / Recurrent thoughts or memories of the most hurtful or terrifying events - Совсем нет/Not at all | GZ2: Навязчивые мысли и воспоминания о наиболее болезненных или пугающих событиях / Recurrent thoughts or memories of the most hurtful or terrifying events - Немного/A little | HA2: Навязчивые мысли и воспоминания о наиболее болезненных или пугающих событиях / Recurrent thoughts or memories of the most hurtful or terrifying events - Довольно сильно/Quite a bit | HB2: Навязчивые мысли и воспоминания о наиболее болезненных или пугающих событиях / Recurrent thoughts or memories of the most hurtful or terrifying events - Очень сильно/Extremely | HC2: Ощущение, что это событие повторяется вновь / Feeling as though the event is happening again - Совсем нет/Not at all | HD2: Ощущение, что это событие повторяется вновь / Feeling as though the event is happening again - Немного/A little | HE2: Ощущение, что это событие повторяется вновь / Feeling as though the event is happening again - Довольно сильно/Quite a bit | HF2: Ощущение, что это событие повторяется вновь / Feeling as though the event is happening again - Очень сильно/Extremely | HG2: Повторяющиеся ночные кошмары / Recurrent nightmares - Совсем нет/Not at all | HH2: Повторяющиеся ночные кошмары / Recurrent nightmares - Немного/A little | HI2: Повторяющиеся ночные кошмары / Recurrent nightmares - Довольно сильно/Quite a bit | HJ2: Повторяющиеся ночные кошмары / Recurrent nightmares - Очень сильно/Extremely | HK2: Ощущение отовранности или отчужденности от людей / Feeling detached or withdrawn from people - Совсем нет/Not at all | HL2: Ощущение отовранности или отчужденности от людей / Feeling detached or withdrawn from people - Немного/A little | HM2: Ощущение отовранности или отчужденности от людей / Feeling detached or withdrawn from people - Довольно сильно/Quite a bit | HN2: Ощущение отовранности или отчужденности от людей / Feeling detached or withdrawn from people - Очень сильно/Extremely | HO2: Неспособность испытывать эмоции / Unable to feel emotions - Совсем нет/Not at all | HP2: Неспособность испытывать эмоции / Unable to feel emotions - Немного/A little | HQ2: Неспособность испытывать эмоции / Unable to feel emotions - Довольно сильно/Quite a bit | HR2: Неспособность испытывать эмоции / Unable to feel emotions - Очень сильно/Extremely | HS2: Нервозность, вздрагивание / Feeling jumpy, easily startled - Совсем нет/Not at all | HT2: Нервозность, вздрагивание / Feeling jumpy, easily startled - Немного/A little | HU2: Нервозность, вздрагивание / Feeling jumpy, easily startled - Довольно сильно/Quite a bit | HV2: Нервозность, вздрагивание / Feeling jumpy, easily startled - Очень сильно/Extremely | HW2: Трудности с концентрацией внимания / Difficulty concentrating - Совсем нет/Not at all | HX2: Трудности с концентрацией внимания / Difficulty concentrating - Немного/A little | HY2: Трудности с концентрацией внимания / Difficulty concentrating - Довольно сильно/Quite a bit | HZ2: Трудности с концентрацией внимания / Difficulty concentrating - Очень сильно/Extremely | IA2: Проблемы со сном / Trouble sleeping - Совсем нет/Not at all | IB2: Проблемы со сном / Trouble sleeping - Немного/A little | IC2: Проблемы со сном / Trouble sleeping - Довольно сильно/Quite a bit | ID2: Проблемы со сном / Trouble sleeping - Очень сильно/Extremely | IE2: Постоянно настороже / Feeling on guard - Совсем нет/Not at all | IF2: Постоянно настороже / Feeling on guard - Немного/A little | IG2: Постоянно настороже / Feeling on guard - Довольно сильно/Quite a bit | IH2: Постоянно настороже / Feeling on guard - Очень сильно/Extremely | II2: Легко раздражаетесь, испытываете вспышки гнева / Feeling irritable or having outbursts of anger - Совсем нет/Not at all | IJ2: Легко раздражаетесь, испытываете вспышки гнева / Feeling irritable or having outbursts of anger - Немного/A little | IK2: Легко раздражаетесь, испытываете вспышки гнева / Feeling irritable or having outbursts of anger - Довольно сильно/Quite a bit | IL2: Легко раздражаетесь, испытываете вспышки гнева / Feeling irritable or having outbursts of anger - Очень сильно/Extremely | IM2: Избегания действий, которые напоминают вам о траматическом или болезненном событии. / Avoiding activities that remind you of the traumatic or hurtful event - Совсем нет/Not at all | IN2: Избегания действий, которые напоминают вам о траматическом или болезненном событии. / Avoiding activities that remind you of the traumatic or hurtful event - Немного/A little | IO2: Избегания действий, которые напоминают вам о траматическом или болезненном событии. / Avoiding activities that remind you of the traumatic or hurtful event - Довольно сильно/Quite a bit | IP2: Избегания действий, которые напоминают вам о траматическом или болезненном событии. / Avoiding activities that remind you of the traumatic or hurtful event - Очень сильно/Extremely | IQ2: Невозможность вспомнить фрагменты наиболее болезненных или травматичных событий / Inability to remember parts of the most hurtful or traumatic events - Совсем нет/Not at all | IR2: Невозможность вспомнить фрагменты наиболее болезненных или травматичных событий / Inability to remember parts of the most hurtful or traumatic events - Немного/A little | IS2: Невозможность вспомнить фрагменты наиболее болезненных или травматичных событий / Inability to remember parts of the most hurtful or traumatic events - Довольно сильно/Quite a bit | IT2: Невозможность вспомнить фрагменты наиболее болезненных или травматичных событий / Inability to remember parts of the most hurtful or traumatic events - Очень сильно/Extremely | IU2: Пониженный интерес к повседневной деятельности / Less interest in daily activities - Совсем нет/Not at all | IV2: Пониженный интерес к повседневной деятельности / Less interest in daily activities - Немного/A little | IW2: Пониженный интерес к повседневной деятельности / Less interest in daily activities - Довольно сильно/Quite a bit | IX2: Пониженный интерес к повседневной деятельности / Less interest in daily activities - Очень сильно/Extremely | IY2: Чувство, что у вас нет будущего / Feeling as if you don’t have a future - Совсем нет/Not at all | IZ2: Чувство, что у вас нет будущего / Feeling as if you don’t have a future - Немного/A little | JA2: Чувство, что у вас нет будущего / Feeling as if you don’t have a future - Довольно сильно/Quite a bit | JB2: Чувство, что у вас нет будущего / Feeling as if you don’t have a future - Очень сильно/Extremely | JC2: Избегание мыслей и чувств, которые ассоциируются с траматичными или болезненными собиытиями / Avoiding thoughts or feelings associated with the traumatic or hurtful events - Совсем нет/Not at all | JD2: Избегание мыслей и чувств, которые ассоциируются с траматичными или болезненными собиытиями / Avoiding thoughts or feelings associated with the traumatic or hurtful events - Немного/A little | JE2: Избегание мыслей и чувств, которые ассоциируются с траматичными или болезненными собиытиями / Avoiding thoughts or feelings associated with the traumatic or hurtful events - Довольно сильно/Quite a bit | JF2: Избегание мыслей и чувств, которые ассоциируются с траматичными или болезненными собиытиями / Avoiding thoughts or feelings associated with the traumatic or hurtful events - Очень сильно/Extremely | JG2: Внезапная эмоциональная или физическая реакция при напоминании об особенно болезненном или травматичном событии / Sudden emotional or physical reaction when reminded of the most hurtful or traumatic events - Совсем нет/Not at all | JH2: Внезапная эмоциональная или физическая реакция при напоминании об особенно болезненном или травматичном событии / Sudden emotional or physical reaction when reminded of the most hurtful or traumatic events - Немного/A little | JI2: Внезапная эмоциональная или физическая реакция при напоминании об особенно болезненном или травматичном событии / Sudden emotional or physical reaction when reminded of the most hurtful or traumatic events - Довольно сильно/Quite a bit | JJ2: Внезапная эмоциональная или физическая реакция при напоминании об особенно болезненном или травматичном событии / Sudden emotional or physical reaction when reminded of the most hurtful or traumatic events - Очень сильно/Extremely | JK2: Ощущение, что мир очень опасен / Feeling that the world is a very dangerous place - Совсем нет/Not at all | JL2: Ощущение, что мир очень опасен / Feeling that the world is a very dangerous place - Немного/A little | JM2: Ощущение, что мир очень опасен / Feeling that the world is a very dangerous place - Довольно сильно/Quite a bit | JN2: Ощущение, что мир очень опасен / Feeling that the world is a very dangerous place - Очень сильно/Extremely | JO2: Ощущение, что вы плохой человек / Feeling that you are a bad person - Совсем нет/Not at all | JP2: Ощущение, что вы плохой человек / Feeling that you are a bad person - Немного/A little | JQ2: Ощущение, что вы плохой человек / Feeling that you are a bad person - Довольно сильно/Quite a bit | JR2: Ощущение, что вы плохой человек / Feeling that you are a bad person - Очень сильно/Extremely | JS2: Обвинение себя в том, что произошло / Blaming yourself for the traumatic event - Совсем нет/Not at all | JT2: Обвинение себя в том, что произошло / Blaming yourself for the traumatic event - Немного/A little | JU2: Обвинение себя в том, что произошло / Blaming yourself for the traumatic event - Довольно сильно/Quite a bit | JV2: Обвинение себя в том, что произошло / Blaming yourself for the traumatic event - Очень сильно/Extremely | JW2: Сильное чувство страха, ужаса, злости, вины или стыда, когда думаете о травматическом событии / Strong feeling of fear, horror, anger, guilt or shame when thinking about the traumatic event - Совсем нет/Not at all | JX2: Сильное чувство страха, ужаса, злости, вины или стыда, когда думаете о травматическом событии / Strong feeling of fear, horror, anger, guilt or shame when thinking about the traumatic event - Немного/A little | JY2: Сильное чувство страха, ужаса, злости, вины или стыда, когда думаете о травматическом событии / Strong feeling of fear, horror, anger, guilt or shame when thinking about the traumatic event - Довольно сильно/Quite a bit | JZ2: Сильное чувство страха, ужаса, злости, вины или стыда, когда думаете о травматическом событии / Strong feeling of fear, horror, anger, guilt or shame when thinking about the traumatic event - Очень сильно/Extremely | KA2: Сложности с чувствами любви и счастья / Difficulty feeling love or happiness - Совсем нет/Not at all | KB2: Сложности с чувствами любви и счастья / Difficulty feeling love or happiness - Немного/A little | KC2: Сложности с чувствами любви и счастья / Difficulty feeling love or happiness - Довольно сильно/Quite a bit | KD2: Сложности с чувствами любви и счастья / Difficulty feeling love or happiness - Очень сильно/Extremely | KE2: Совершение рискованных поступков, которые могут повредить вам или окружающим / Taking risks that may harm yourself or others - Совсем нет/Not at all | KF2: Совершение рискованных поступков, которые могут повредить вам или окружающим / Taking risks that may harm yourself or others - Немного/A little | KG2: Совершение рискованных поступков, которые могут повредить вам или окружающим / Taking risks that may harm yourself or others - Довольно сильно/Quite a bit | KH2: Совершение рискованных поступков, которые могут повредить вам или окружающим / Taking risks that may harm yourself or others - Очень сильно/Extremely | KI2: Ощущение, что травматическое событие повредило вас как личность / Feeling like you have been damaged as a person by the traumatic event - Совсем нет/Not at all | KJ2: Ощущение, что травматическое событие повредило вас как личность / Feeling like you have been damaged as a person by the traumatic event - Немного/A little | KK2: Ощущение, что травматическое событие повредило вас как личность / Feeling like you have been damaged as a person by the traumatic event - Довольно сильно/Quite a bit | KL2: Ощущение, что травматическое событие повредило вас как личность / Feeling like you have been damaged as a person by the traumatic event - Очень сильно/Extremely | KM2: Ощущение, будто если что-то напоминает вам о травматическом событии, это похоже на сон, что это не случилось с вами и/или это не произошло в реальности / Feeling as if something reminds you of the trauma but it feels like a dream, that it is not happening to you, and/or that it is not real - Совсем нет/Not at all | KN2: Ощущение, будто если что-то напоминает вам о травматическом событии, это похоже на сон, что это не случилось с вами и/или это не произошло в реальности / Feeling as if something reminds you of the trauma but it feels like a dream, that it is not happening to you, and/or that it is not real - Немного/A little | KO2: Ощущение, будто если что-то напоминает вам о травматическом событии, это похоже на сон, что это не случилось с вами и/или это не произошло в реальности / Feeling as if something reminds you of the trauma but it feels like a dream, that it is not happening to you, and/or that it is not real - Довольно сильно/Quite a bit | KP2: Ощущение, будто если что-то напоминает вам о травматическом событии, это похоже на сон, что это не случилось с вами и/или это не произошло в реальности / Feeling as if something reminds you of the trauma but it feels like a dream, that it is not happening to you, and/or that it is not real - Очень сильно/Extremely | KQ2: Ощущение, что люди и предметы вокруг вас не настоящие или не знакомые / Feeling people or objects around you are not real or strange - Совсем нет/Not at all | KR2: Ощущение, что люди и предметы вокруг вас не настоящие или не знакомые / Feeling people or objects around you are not real or strange - Немного/A little | KS2: Ощущение, что люди и предметы вокруг вас не настоящие или не знакомые / Feeling people or objects around you are not real or strange - Довольно сильно/Quite a bit | KT2: Ощущение, что люди и предметы вокруг вас не настоящие или не знакомые / Feeling people or objects around you are not real or strange - Очень сильно/Extremely | KU2: Совсем нет / Not at all | KV2: Немного / A little | KW2: Довольно сильно / Quite a bit | KX2: Очень сильно / Extremely | KY2: Совсем нет / Not at all | KZ2: Немного / A little | LA2: Довольно сильно / Quite a bit | LB2: Очень сильно / Extremely | LC2: Совсем нет / Not at all | LD2: Немного / A little | LE2: Довольно сильно / Quite a bit | LF2: Очень сильно / Extremely | LG2: Совсем нет / Not at all | LH2: Немного / A little | LI2: Довольно сильно / Quite a bit | LJ2: Очень сильно / Extremely | LK2: Совсем нет / Not at all | LL2: Немного / A little | LM2: Довольно сильно / Quite a bit | LN2: Очень сильно / Extremely | LO2: Совсем нет / Not at all | LP2: Немного / A little | LQ2: Довольно сильно / Quite a bit | LR2: Очень сильно / Extremely | LS2: Совсем нет / Not at all | LT2: Немного / A little | LU2: Довольно сильно / Quite a bit | LV2: Очень сильно / Extremely | LW2: Совсем нет / Not at all | LX2: Немного / A little | LY2: Довольно сильно / Quite a bit | LZ2: Очень сильно / Extremely | MA2: Совсем нет / Not at all | MB2: Немного / A little | MC2: Довольно сильно / Quite a bit | MD2: Очень сильно / Extremely | ME2: Совсем нет / Not at all | MF2: Немного / A little | MG2: Довольно сильно / Quite a bit | MH2: Очень сильно / Extremely | MI2: Совсем нет / Not at all | MJ2: Немного / A little | MK2: Довольно сильно / Quite a bit | ML2: Очень сильно / Extremely | MM2: Совсем нет / Not at all | MN2: Немного / A little | MO2: Довольно сильно / Quite a bit | MP2: Очень сильно / Extremely | MQ2: Совсем нет / Not at all | MR2: Немного / A little | MS2: Довольно сильно / Quite a bit | MT2: Очень сильно / Extremely | MU2: Совсем нет / Not at all | MV2: Немного / A little | MW2: Довольно сильно / Quite a bit | MX2: Очень сильно / Extremely | MY2: Совсем нет / Not at all | MZ2: Немного / A little | NA2: Довольно сильно / Quite a bit | NB2: Очень сильно / Extremely | NC2: Совсем нет / Not at all | ND2: Немного / A little | NE2: Довольно сильно / Quite a bit | NF2: Очень сильно / Extremely | NG2: Совсем нет / Not at all | NH2: Немного / A little | NI2: Довольно сильно / Quite a bit | NJ2: Очень сильно / Extremely | NK2: Совсем нет / Not at all | NL2: Немного / A little | NM2: Довольно сильно / Quite a bit | NN2: Очень сильно / Extremely | NO2: Совсем нет / Not at all | NP2: Немного / A little | NQ2: Довольно сильно / Quite a bit | NR2: Очень сильно / Extremely | NS2: Совсем нет / Not at all | NT2: Немного / A little | NU2: Довольно сильно / Quite a bit | NV2: Очень сильно / Extremely | NW2: Совсем нет / Not at all | NX2: Немного / A little | NY2: Довольно сильно / Quite a bit | NZ2: Очень сильно / Extremely | OA2: Совсем нет / Not at all | OB2: Немного / A little | OC2: Довольно сильно / Quite a bit | OD2: Очень сильно / Extremely | OE2: Совсем нет / Not at all | OF2: Немного / A little | OG2: Довольно сильно / Quite a bit | OH2: Очень сильно / Extremely | OI2: Совсем нет / Not at all | OJ2: Немного / A little | OK2: Довольно сильно / Quite a bit | OL2: Очень сильно / Extremely
A3: SC001 | B3: Да / Yes | D3: Да / Yes | F3: Да / Yes | I3: Мужской / Male | M3: 25-34 | S3: Беларус | T3: Русский, Английский | U3: Санкт-Петербург | V3: Тбилиси | AB3: Никогда не был женат (замужем) / Single, never married | AE3: Нет / No | AF3: 0 | AH3: Нет / No | AI3: 0 | AL3: Незаконченное высшее / Some college | AT3: Выше среднего / Above average | AU3: It's more exciting to join the common panic party, rather than staying home | AX3: Скорее не согласен / Moderately disagree | BA3: Скорее согласен / Moderately agree | BD3: Полностью согласен / Strongly agree | BK3: Полностью не согласен / Strongly disagree | BO3: Полностью не согласен / Strongly disagree | BS3: Полностью не согласен / Strongly disagree | BW3: Полностью не согласен / Strongly disagree | BX3: Полностью согласен / Strongly agree | CE3: Полностью не согласен / Strongly disagree | CF3: Полностью согласен / Strongly agree | CL3: Скорее не согласен / Moderately disagree | CQ3: Полностью не согласен / Strongly disagree | CU3: Полностью не согласен / Strongly disagree | CY3: Полностью не согласен / Strongly disagree | DC3: Полностью не согласен / Strongly disagree | DG3: Полностью не согласен / Strongly disagree | DK3: Полностью не согласен / Strongly disagree | DL3: Полностью согласен / Strongly agree | DS3: Полностью не согласен / Strongly disagree | DW3: Полностью не согласен / Strongly disagree | EA3: Полностью не согласен / Strongly disagree | EE3: Полностью не согласен / Strongly disagree | EI3: Полностью не согласен / Strongly disagree | EM3: Полностью не согласен / Strongly disagree | EO3: Скорее согласен / Moderately agree | ET3: Скорее не согласен / Moderately disagree | EY3: Полностью не согласен / Strongly disagree | FA3: Скорее согласен / Moderately agree | FF3: Скорее не согласен / Moderately disagree | FK3: Полностью не согласен / Strongly disagree | FN3: Скорее не согласен / Moderately disagree | FQ3: Нет / No | FS3: Нет / No | FU3: Нет / No | FW3: Нет / No | FY3: Нет / No | GA3: Нет / No | GC3: Нет / No | GE3: Нет / No | GG3: Нет / No | GI3: Нет / No | GK3: Нет / No | GM3: Нет / No | GO3: Нет / No | GQ3: Нет / No | GS3: Нет / No | GU3: Нет / No | GW3: Нет / No | GX3: Нарушение медицинской этики, введение в наркоз против моей воли, проведение операции против моей воли | HB3: Очень сильно/Extremely | HC3: Совсем нет/Not at all | HG3: Совсем нет/Not at all | HK3: Совсем нет/Not at all | HO3: Совсем нет/Not at all | HU3: Довольно сильно/Quite a bit | HW3: Совсем нет/Not at all | IA3: Совсем нет/Not at all | IE3: Совсем нет/Not at all | IK3: Довольно сильно/Quite a bit | IP3: Очень сильно/Extremely | IQ3: Совсем нет/Not at all | IV3: Немного/A little | IY3: Совсем нет/Not at all | JC3: Совсем нет/Not at all | JI3: Довольно сильно/Quite a bit | JL3: Немного/A little | JO3: Совсем нет/Not at all | JS3: Совсем нет/Not at all | JY3: Довольно сильно/Quite a bit | KA3: Совсем нет/Not at all | KF3: Немного/A little | KJ3: Немного/A little | KM3: Совсем нет/Not at all | KQ3: Совсем нет/Not at all | KU3: Совсем нет / Not at all | KY3: Совсем нет / Not at all | LC3: Совсем нет / Not at all | LG3: Совсем нет / Not at all | LK3: Совсем нет / Not at all | LO3: Совсем нет / Not at all | LS3: Совсем нет / Not at all | LW3: Совсем нет / Not at all | MA3: Совсем нет / Not at all | ME3: Совсем нет / Not at all | MI3: Совсем нет / Not at all | MM3: Совсем нет / Not at all | MQ3: Совсем нет / Not at all | MV3: Немного / A little | MZ3: Немного / A little | NC3: Совсем нет / Not at all | NG3: Совсем нет / Not at all | NK3: Совсем нет / Not at all | NO3: Совсем нет / Not at all | NS3: Совсем нет / Not at all | NX3: Немного / A little | OA3: Совсем нет / Not at all | OE3: Совсем нет / Not at all | OJ3: Немного / A little
A4: CF002 | B4: Да / Yes | D4: Да / Yes | F4: Да / Yes | H4: Женский / Female | N4: 35-44 | S4: еврейка | T4: русский, английский, немного иврит, немного немецкий | U4: Москва | V4: Армения, Ереван | W4: Женат (замужем) / Married | AD4: Да / Yes | AF4: 1 | AH4: Нет / No | AI4: - | AL4: Незаконченное высшее / Some college | AR4: Ниже среднего / Below average | AU4: Из-за того, что Россия ведёт захватническую войну | AX4: Скорее не согласен / Moderately disagree | BA4: Скорее согласен / Moderately agree | BG4: Полностью не согласен / Strongly disagree | BK4: Полностью не согласен / Strongly disagree | BN4: Скорее не согласен / Moderately disagree | BS4: Полностью не согласен / Strongly disagree | BV4: Скорее не согласен / Moderately disagree | BY4: Скорее согласен / Moderately agree | CD4: Скорее не согласен / Moderately disagree | CI4: Полностью не согласен / Strongly disagree | CL4: Скорее не согласен / Moderately disagree | CO4: Скорее согласен / Moderately agree | CS4: Скорее согласен / Moderately agree | CX4: Скорее не согласен / Moderately disagree | DB4: Скорее не согласен / Moderately disagree | DE4: Скорее согласен / Moderately agree | DH4: Полностью согласен / Strongly agree | DL4: Полностью согласен / Strongly agree | DQ4: Скорее согласен / Moderately agree | DU4: Скорее согласен / Moderately agree | EA4: Полностью не согласен / Strongly disagree | EC4: Скорее согласен / Moderately agree | EI4: Полностью не согласен / Strongly disagree | EL4: Скорее не согласен / Moderately disagree | EQ4: Полностью не согласен / Strongly disagree | ET4: Скорее не согласен / Moderately disagree | EW4: Скорее согласен / Moderately agree | FB4: Скорее не согласен / Moderately disagree | FF4: Скорее не согласен / Moderately disagree | FH4: Полностью согласен / Strongly agree | FN4: Скорее не согласен / Moderately disagree | FQ4: Нет / No | FS4: Нет / No | FU4: Нет / No | FW4: Нет / No | FY4: Нет / No | GA4: Нет / No | GB4: Да / Yes | GD4: Да / Yes | GF4: Да / Yes | GI4: Нет / No | GJ4: Да / Yes | GL4: Да / Yes | GN4: Да / Yes | GQ4: Нет / No | GS4: Нет / No | GU4: Нет / No | GW4: Нет / No | GZ4: Немного/A little | HC4: Совсем нет/Not at all | HG4: Совсем нет/Not at all | HK4: Совсем нет/Not at all | HO4: Совсем нет/Not at all | HT4: Немного/A little | HW4: Совсем нет/Not at all | IC4: Довольно сильно/Quite a bit | IE4: Совсем нет/Not at all | II4: Совсем нет/Not at all | IM4: Совсем нет/Not at all | IQ4: Совсем нет/Not at all | IW4: Довольно сильно/Quite a bit | IY4: Совсем нет/Not at all | JD4: Немного/A little | JG4: Совсем нет/Not at all | JL4: Немного/A little | JR4: Очень сильно/Extremely | JT4: Немного/A little | JY4: Довольно сильно/Quite a bit | KB4: Немного/A little | KE4: Совсем нет/Not at all | KK4: Довольно сильно/Quite a bit | KM4: Совсем нет/Not at all | KQ4: Совсем нет/Not at all | KU4: Совсем нет / Not at all | KY4: Совсем нет / Not at all | LD4: Немного / A little | LG4: Совсем нет / Not at all | LK4: Совсем нет / Not at all | LO4: Совсем нет / Not at all | LT4: Немного / A little | LW4: Совсем нет / Not at all | MA4: Совсем нет / Not at all | MF4: Немного / A little | MK4: Довольно сильно / Quite a bit | MO4: Довольно сильно / Quite a bit | MQ4: Совсем нет / Not at all | MW4: Довольно сильно / Quite a bit | MY4: Совсем нет / Not at all | NE4: Довольно сильно / Quite a bit | NG4: Совсем нет / Not at all | NM4: Довольно сильно / Quite a bit | NO4: Совсем нет / Not at all | NS4: Совсем нет / Not at all | NW4: Совсем нет / Not at all | OA4: Совсем нет / Not at all | OH4: Очень сильно / Extremely | OL4: Очень сильно / Extremely
A5: CT001 | B5: Да / Yes | D5: Да / Yes | F5: Да / Yes | I5: Мужской / Male | M5: 25-34 | R5: Русский(ая) / Russian | T5: Русский, английский (не очень хорошо знаю) | U5: Красноармейск, Московская область | V5: Тбилиси, Грузия | AB5: Никогда не был женат (замужем) / Single, never married | AE5: Нет / No | AF5: Нет | AH5: Нет / No | AI5: Нет | AL5: Незаконченное высшее / Some college | AR5: Ниже среднего / Below average | AU5: Риск политического преследования и мобилизации | AY5: Полностью не согласен / Strongly disagree | BB5: Скорее не согласен / Moderately disagree | BF5: Скорее не согласен / Moderately disagree | BJ5: Скорее не согласен / Moderately disagree | BN5: Скорее не согласен / Moderately disagree | BS5: Полностью не согласен / Strongly disagree | BV5: Скорее не согласен / Moderately disagree | CA5: Полностью не согласен / Strongly disagree | CD5: Скорее не согласен / Moderately disagree | CH5: Скорее не согласен / Moderately disagree | CM5: Полностью не согласен / Strongly disagree | CQ5: Полностью не согласен / Strongly disagree | CT5: Скорее не согласен / Moderately disagree | CX5: Скорее не согласен / Moderately disagree | DB5: Скорее не согласен / Moderately disagree | DG5: Полностью не согласен / Strongly disagree | DK5: Полностью не согласен / Strongly disagree | DN5: Скорее не согласен / Moderately disagree | DP5: Полностью согласен / Strongly agree | DT5: Полностью согласен / Strongly agree | EA5: Полностью не согласен / Strongly disagree | ED5: Скорее не согласен / Moderately disagree | EH5: Скорее не согласен / Moderately disagree | EM5: Полностью не согласен / Strongly disagree | EP5: Скорее не согласен / Moderately disagree | ES5: Скорее согласен / Moderately agree | EV5: Полностью согласен / Strongly agree | FC5: Полностью не согласен / Strongly disagree | FF5: Скорее не согласен / Moderately disagree | FJ5: Скорее не согласен / Moderately disagree | FM5: Скорее согласен / Moderately agree | FQ5: Нет / No | FS5: Нет / No | FU5: Нет / No | FW5: Нет / No | FY5: Нет / No | GA5: Нет / No | GC5: Нет / No | GD5: Да / Yes | GG5: Нет / No | GH5: Да / Yes | GK5: Нет / No | GL5: Да / Yes | GN5: Да / Yes | GQ5: Нет / No | GS5: Нет / No | GU5: Нет / No | GW5: Нет / No | GX5: Донос на работе, мобилизация, угрозы в соц. сетях, деятельность, за которую могут посадить | GY5: Совсем нет/Not at all | HC5: Совсем нет/Not at all | HH5: Немного/A little | HK5: Совсем нет/Not at all | HO5: Совсем нет/Not at all | HS5: Совсем нет/Not at all | HX5: Немного/A little | IA5: Совсем нет/Not at all | IE5: Совсем нет/Not at all | II5: Совсем нет/Not at all | IM5: Совсем нет/Not at all | IQ5: Совсем нет/Not at all | IU5: Совсем нет/Not at all | IZ5: Немного/A little | JC5: Совсем нет/Not at all | JG5: Совсем нет/Not at all | JK5: Совсем нет/Not at all | JP5: Немного/A little | JT5: Немного/A little | JW5: Совсем нет/Not at all | KA5: Совсем нет/Not at all | KE5: Совсем нет/Not at all | KI5: Совсем нет/Not at all | KM5: Совсем нет/Not at all | KQ5: Совсем нет/Not at all | KU5: Совсем нет / Not at all | KY5: Совсем нет / Not at all | LC5: Совсем нет / Not at all | LG5: Совсем нет / Not at all | LK5: Совсем нет / Not at all | LO5: Совсем нет / Not at all | LS5: Совсем нет / Not at all | LW5: Совсем нет / Not at all | MA5: Совсем нет / Not at all | ME5: Совсем нет / Not at all | MI5: Совсем нет / Not at all | MM5: Совсем нет / Not at all | MQ5: Совсем нет / Not at all | MU5: Совсем нет / Not at all | MY5: Совсем нет / Not at all | NC5: Совсем нет / Not at all | NH5: Немного / A little | NK5: Совсем нет / Not at all | NP5: Немного / A little | NS5: Совсем нет / Not at all | NW5: Совсем нет / Not at all | OB5: Немного / A little | OF5: Немного / A little | OJ5: Немного / A little
A6: GU001 | B6: Да / Yes | D6: Да / Yes | F6: Да / Yes | H6: Женский / Female | N6: 35-44 | R6: Русский(ая) / Russian | T6: Русский, английский | U6: Москва | V6: Батуми, Грузия | W6: Женат (замужем) / Married | AD6: Да / Yes | AF6: 1 | AH6: Нет / No | AI6: нет | AN6: Высшее образование (специалист) / 5 years of college | AS6: Средний / Average | AU6: Воссоединиться с мужем, котрый уехал раньше из-за мобилизации | AY6: Полностью не согласен / Strongly disagree | BA6: Скорее согласен / Moderately agree | BF6: Скорее не согласен / Moderately disagree | BK6: Полностью не согласен / Strongly disagree | BO6: Полностью не согласен / Strongly disagree | BQ6: Скорее согласен / Moderately agree | BW6: Полностью не согласен / Strongly disagree | CA6: Полностью не согласен / Strongly disagree | CE6: Полностью не согласен / Strongly disagree | CI6: Полностью не согласен / Strongly disagree | CK6: Скорее согласен / Moderately agree | CP6: Скорее не согласен / Moderately disagree | CU6: Полностью не согласен / Strongly disagree | CY6: Полностью не согласен / Strongly disagree | DC6: Полностью не согласен / Strongly disagree | DD6: Полностью согласен / Strongly agree | DK6: Полностью не согласен / Strongly disagree | DN6: Скорее не согласен / Moderately disagree | DR6: Скорее не согласен / Moderately disagree | DW6: Полностью не согласен / Strongly disagree | EA6: Полностью не согласен / Strongly disagree | EE6: Полностью не согласен / Strongly disagree | EI6: Полностью не согласен / Strongly disagree | EM6: Полностью не согласен / Strongly disagree | EQ6: Полностью не согласен / Strongly disagree | EU6: Полностью не согласен / Strongly disagree | EW6: Скорее согласен / Moderately agree | FC6: Полностью не согласен / Strongly disagree | FG6: Полностью не согласен / Strongly disagree | FH6: Полностью согласен / Strongly agree | FM6: Скорее согласен / Moderately agree | FQ6: Нет / No | FS6: Нет / No | FU6: Нет / No | FW6: Нет / No | FY6: Нет / No | GA6: Нет / No | GB6: Да / Yes | GE6: Нет / No | GG6: Нет / No | GI6: Нет / No | GK6: Нет / No | GM6: Нет / No | GO6: Нет / No | GQ6: Нет / No | GS6: Нет / No | GU6: Нет / No | GW6: Нет / No | GX6: - | GY6: Совсем нет/Not at all | HC6: Совсем нет/Not at all | HG6: Совсем нет/Not at all | HK6: Совсем нет/Not at all | HO6: Совсем нет/Not at all | HS6: Совсем нет/Not at all | HW6: Совсем нет/Not at all | IA6: Совсем нет/Not at all | IE6: Совсем нет/Not at all | II6: Совсем нет/Not at all | IO6: Довольно сильно/Quite a bit | IQ6: Совсем нет/Not at all | IV6: Немного/A little | IZ6: Немного/A little | JC6: Совсем нет/Not at all | JG6: Совсем нет/Not at all | JK6: Совсем нет/Not at all | JO6: Совсем нет/Not at all | JS6: Совсем нет/Not at all | JX6: Немного/A little | KA6: Совсем нет/Not at all | KE6: Совсем нет/Not at all | KJ6: Немного/A little | KM6: Совсем нет/Not at all | KQ6: Совсем нет/Not at all | KU6: Совсем нет / Not at all | KZ6: Немного / A little | LC6: Совсем нет / Not at all | LH6: Немного / A little | LL6: Немного / A little | LP6: Немного / A little | LS6: Совсем нет / Not at all | LX6: Немного / A little | MA6: Совсем нет / Not at all | ME6: Совсем нет / Not at all | MJ6: Немного / A little | MM6: Совсем нет / Not at all | MQ6: Совсем нет / Not at all | MV6: Немного / A little | MY6: Совсем нет / Not at all | NC6: Совсем нет / Not at all | NH6: Немного / A little | NK6: Совсем нет / Not at all | NO6: Совсем нет / Not at all | NS6: Совсем нет / Not at all | NW6: Совсем нет / Not at all | OC6: Довольно сильно / Quite a bit | OE6: Совсем нет / Not at all | OK6: Довольно сильно / Quite a bit
A7: FM002 | B7: Да / Yes | D7: Да / Yes | F7: Да / Yes | I7: Мужской / Male | N7: 35-44 | R7: Русский(ая) / Russian | T7: Русский, английский | U7: Москва | V7: Ереван, Армения | W7: Женат (замужем) / Married | AE7: Нет / No | AF7: 0 | AH7: Нет / No | AI7: 0 | AL7: Незаконченное высшее / Some college | AT7: Выше среднего / Above average | AU7: Опасения за свою жизнь, нежелание платить налоги на "СВО" | AW7: Скорее согласен / Moderately agree | BB7: Скорее не согласен / Moderately disagree | BF7: Скорее не согласен / Moderately disagree | BI7: Скорее согласен / Moderately agree | BL7: Полностью согласен / Strongly agree | BS7: Полностью не согласен / Strongly disagree | BW7: Полностью не согласен / Strongly disagree | BZ7: Скорее не согласен / Moderately disagree | CD7: Скорее не согласен / Moderately disagree | CH7: Скорее не согласен / Moderately disagree | CM7: Полностью не согласен / Strongly disagree | CO7: Скорее согласен / Moderately agree | CS7: Скорее согласен / Moderately agree | CX7: Скорее не согласен / Moderately disagree | DB7: Скорее не согласен / Moderately disagree | DE7: Скорее согласен / Moderately agree | DH7: Полностью согласен / Strongly agree | DM7: Скорее согласен / Moderately agree | DR7: Скорее не согласен / Moderately disagree | DV7: Скорее не согласен / Moderately disagree | DZ7: Скорее не согласен / Moderately disagree | EC7: Скорее согласен / Moderately agree | EI7: Полностью не согласен / Strongly disagree | EM7: Полностью не согласен / Strongly disagree | EP7: Скорее не согласен / Moderately disagree | ET7: Скорее не согласен / Moderately disagree | EX7: Скорее не согласен / Moderately disagree | FB7: Скорее не согласен / Moderately disagree | FF7: Скорее не согласен / Moderately disagree | FH7: Полностью согласен / Strongly agree | FM7: Скорее согласен / Moderately agree | FQ7: Нет / No | FS7: Нет / No | FU7: Нет / No | FW7: Нет / No | FY7: Нет / No | GA7: Нет / No | GC7: Нет / No | GD7: Да / Yes | GG7: Нет / No | GH7: Да / Yes | GJ7: Да / Yes | GL7: Да / Yes | GN7: Да / Yes | GQ7: Нет / No | GS7: Нет / No | GU7: Нет / No | GW7: Нет / No | GX7: Начало "СВО", начало мобилизации | HA7: Довольно сильно/Quite a bit | HE7: Довольно сильно/Quite a bit | HH7: Немного/A little | HM7: Довольно сильно/Quite a bit | HP7: Немного/A little | HT7: Немного/A little | HX7: Немного/A little | IC7: Довольно сильно/Quite a bit | IH7: Очень сильно/Extremely | IJ7: Немного/A little | IP7: Очень сильно/Extremely | IQ7: Совсем нет/Not at all | IV7: Немного/A little | IZ7: Немного/A little | JD7: Немного/A little | JI7: Довольно сильно/Quite a bit | JN7: Очень сильно/Extremely | JP7: Немного/A little | JU7: Довольно сильно/Quite a bit | JY7: Довольно сильно/Quite a bit | KC7: Довольно сильно/Quite a bit | KE7: Совсем нет/Not at all | KJ7: Немного/A little | KM7: Совсем нет/Not at all | KQ7: Совсем нет/Not at all | KW7: Довольно сильно / Quite a bit | LA7: Довольно сильно / Quite a bit | LD7: Немного / A little | LI7: Довольно сильно / Quite a bit | LN7: Очень сильно / Extremely | LP7: Немного / A little | LU7: Довольно сильно / Quite a bit | LW7: Совсем нет / Not at all | MB7: Немного / A little | MH7: Очень сильно / Extremely | MJ7: Немного / A little | MO7: Довольно сильно / Quite a bit | MS7: Довольно сильно / Quite a bit | MW7: Довольно сильно / Quite a bit | MY7: Совсем нет / Not at all | NE7: Довольно сильно / Quite a bit | NH7: Немного / A little | NM7: Довольно сильно / Quite a bit | NQ7: Довольно сильно / Quite a bit | NU7: Довольно сильно / Quite a bit | NY7: Довольно сильно / Quite a bit | OB7: Немного / A little | OF7: Немного / A little | OI7: Совсем нет / Not at all
A8: FM001 | B8: Да / Yes | D8: Да / Yes | F8: Да / Yes | I8: Мужской / Male | O8: 45-54 | R8: Русский(ая) / Russian | T8: Русский, English, Français | U8: Москва | V8: Ереван, Армения | W8: Женат (замужем) / Married | AD8: Да / Yes | AF8: 1 ребенок 17 лет, 3 ребенка старше 18 лет | AH8: Нет / No | AI8: Нет | AN8: Высшее образование (специалист) / 5 years of college | AS8: Средний / Average | AU8: Формально подлежу мобилизации, не хочу участвовать в войне Путина | AX8: Скорее не согласен / Moderately disagree | BC8: Полностью не согласен / Strongly disagree | BG8: Полностью не согласен / Strongly disagree | BK8: Полностью не согласен / Strongly disagree | BN8: Скорее не согласен / Moderately disagree | BR8: Скорее не согласен / Moderately disagree | BV8: Скорее не согласен / Moderately disagree | BZ8: Скорее не согласен / Moderately disagree | CD8: Скорее не согласен / Moderately disagree | CH8: Скорее не согласен / Moderately disagree | CL8: Скорее не согласен / Moderately disagree | CQ8: Полностью не согласен / Strongly disagree | CU8: Полностью не согласен / Strongly disagree | CX8: Скорее не согласен / Moderately disagree | DC8: Полностью не согласен / Strongly disagree | DF8: Скорее не согласен / Moderately disagree | DJ8: Скорее не согласен / Moderately disagree | DN8: Скорее не согласен / Moderately disagree | DQ8: Скорее согласен / Moderately agree | DV8: Скорее не согласен / Moderately disagree | EA8: Полностью не согласен / Strongly disagree | ED8: Скорее не согласен / Moderately disagree | EI8: Полностью не согласен / Strongly disagree | EM8: Полностью не согласен / Strongly disagree | EQ8: Полностью не согласен / Strongly disagree | ES8: Скорее согласен / Moderately agree | EX8: Скорее не согласен / Moderately disagree | FC8: Полностью не согласен / Strongly disagree | FG8: Полностью не согласен / Strongly disagree | FI8: Скорее согласен / Moderately agree | FN8: Скорее не согласен / Moderately disagree | FQ8: Нет / No | FS8: Нет / No | FU8: Нет / No | FW8: Нет / No | FY8: Нет / No | GA8: Нет / No | GC8: Нет / No | GE8: Нет / No | GG8: Нет / No | GI8: Нет / No | GK8: Нет / No | GM8: Нет / No | GO8: Нет / No | GQ8: Нет / No | GS8: Нет / No | GU8: Нет / No | GW8: Нет / No | GX8: В Армении угрожающих ситуаций не было | GY8: Совсем нет/Not at all | HC8: Совсем нет/Not at all | HG8: Совсем нет/Not at all | HL8: Немного/A little | HO8: Совсем нет/Not at all | HS8: Совсем нет/Not at all | HW8: Совсем нет/Not at all | IA8: Совсем нет/Not at all | IE8: Совсем нет/Not at all | II8: Совсем нет/Not at all | IM8: Совсем нет/Not at all | IQ8: Совсем нет/Not at all | IU8: Совсем нет/Not at all | IZ8: Немного/A little | JD8: Немного/A little | JG8: Совсем нет/Not at all | JK8: Совсем нет/Not at all | JO8: Совсем нет/Not at all | JS8: Совсем нет/Not at all | JW8: Совсем нет/Not at all | KA8: Совсем нет/Not at all | KF8: Немного/A little | KI8: Совсем нет/Not at all | KM8: Совсем нет/Not at all | KQ8: Совсем нет/Not at all | KV8: Немного / A little | KY8: Совсем нет / Not at all | LC8: Совсем нет / Not at all | LH8: Немного / A little | LK8: Совсем нет / Not at all | LO8: Совсем нет / Not at all | LS8: Совсем нет / Not at all | LW8: Совсем нет / Not at all | MA8: Совсем нет / Not at all | MF8: Немного / A little | MJ8: Немного / A little | MN8: Немного / A little | MQ8: Совсем нет / Not at all | MV8: Немного / A little | MY8: Совсем нет / Not at all | ND8: Немного / A little | NH8: Немного / A little | NL8: Немного / A little | NO8: Совсем нет / Not at all | NT8: Немного / A little | NW8: Совсем нет / Not at all | OA8: Совсем нет / Not at all | OE8: Совсем нет / Not at all | OI8: Совсем нет / Not at all
A9: PM001 | B9: Да / Yes | D9: Да / Yes | F9: Да / Yes | H9: Женский / Female | P9: 55-64 | R9: Русский(ая) / Russian | T9: Русский, английский | U9: Москва | V9: Ереван, Армения | W9: Женат (замужем) / Married | AD9: Да / Yes | AF9: 1 | AH9: Нет / No | AN9: Высшее образование (специалист) / 5 years of college | AS9: Средний / Average | AU9: Тревога за мужа, усталось от постоянного напряжения из-за политической обстановки | AX9: Скорее не согласен / Moderately disagree | BA9: Скорее согласен / Moderately agree | BE9: Скорее согласен / Moderately agree | BJ9: Скорее не согласен / Moderately disagree | BN9: Скорее не согласен / Moderately disagree | BR9: Скорее не согласен / Moderately disagree | BU9: Скорее согласен / Moderately agree | BY9: Скорее согласен / Moderately agree | CC9: Скорее согласен / Moderately agree | CH9: Скорее не согласен / Moderately disagree | CL9: Скорее не согласен / Moderately disagree | CP9: Скорее не согласен / Moderately disagree | CT9: Скорее не согласен / Moderately disagree | CX9: Скорее не согласен / Moderately disagree | DB9: Скорее не согласен / Moderately disagree | DD9: Полностью согласен / Strongly agree | DJ9: Скорее не согласен / Moderately disagree | DM9: Скорее согласен / Moderately agree | DQ9: Скорее согласен / Moderately agree | DU9: Скорее согласен / Moderately agree | DZ9: Скорее не согласен / Moderately disagree | ED9: Скорее не согласен / Moderately disagree | EI9: Полностью не согласен / Strongly disagree | EM9: Полностью не согласен / Strongly disagree | EP9: Скорее не согласен / Moderately disagree | ES9: Скорее согласен / Moderately agree | EW9: Скорее согласен / Moderately agree | FB9: Скорее не согласен / Moderately disagree | FG9: Полностью не согласен / Strongly disagree | FH9: Полностью согласен / Strongly agree | FN9: Скорее не согласен / Moderately disagree | FQ9: Нет / No | FS9: Нет / No | FU9: Нет / No | FW9: Нет / No | FY9: Нет / No | GA9: Нет / No | GC9: Нет / No | GE9: Нет / No | GG9: Нет / No | GI9: Нет / No | GK9: Нет / No | GM9: Нет / No | GO9: Нет / No | GQ9: Нет / No | GS9: Нет / No | GU9: Нет / No | GW9: Нет / No | GY9: Совсем нет/Not at all | HC9: Совсем нет/Not at all | HH9: Немного/A little | HL9: Немного/A little | HO9: Совсем нет/Not at all | HS9: Совсем нет/Not at all | HX9: Немного/A little | IA9: Совсем нет/Not at all | IE9: Совсем нет/Not at all | II9: Совсем нет/Not at all | IM9: Совсем нет/Not at all | IQ9: Совсем нет/Not at all | IU9: Совсем нет/Not at all | IZ9: Немного/A little | JD9: Немного/A little | JG9: Совсем нет/Not at all | JL9: Немного/A little | JP9: Немного/A little | JS9: Совсем нет/Not at all | JW9: Совсем нет/Not at all | KA9: Совсем нет/Not at all | KE9: Совсем нет/Not at all | KI9: Совсем нет/Not at all | KM9: Совсем нет/Not at all | KQ9: Совсем нет/Not at all | KU9: Совсем нет / Not at all | KY9: Совсем нет / Not at all | LC9: Совсем нет / Not at all | LG9: Совсем нет / Not at all | LK9: Совсем нет / Not at all | LO9: Совсем нет / Not at all | LS9: Совсем нет / Not at all | LX9: Немного / A little | MA9: Совсем нет / Not at all | MF9: Немного / A little | MJ9: Немного / A little | MM9: Совсем нет / Not at all | MQ9: Совсем нет / Not at all | MV9: Немного / A little | MY9: Совсем нет / Not at all | NC9: Совсем нет / Not at all | NH9: Немного / A little | NL9: Немного / A little | NP9: Немного / A little | NT9: Немного / A little | NX9: Немного / A little | OA9: Совсем нет / Not at all | OF9: Немного / A little | OK9: Довольно сильно / Quite a bit
